#VRML_SIM R2021a utf8
WorldInfo {
  basicTimeStep 16
  coordinateSystem "NUE"
  contactProperties [
    ContactProperties {
      material2 "slippy"
      coulombFriction [
        0
      ]
    }
    ContactProperties {
      material2 "block"
      coulombFriction [
        0.01
      ]
    }
  ]
}
Viewpoint {
  orientation -0.20291877279896828 -0.9274397996662079 -0.3141327579875502 2.304387062814877
  position 0.7538884834678738 0.2944462077355234 0.7069157765126985
}
TexturedBackground {
}
TexturedBackgroundLight {
}
Floor {
  size 2.4 2.4
  appearance Asphalt {
  }
}
DEF Block_R1 Solid {
  translation 0.377 0.05 -0.9
  children [
    DEF BOX_R Shape {
      appearance PBRAppearance {
        baseColor 1 0 0
        metalness 0
      }
      geometry Box {
        size 0.05 0.05 0.05
      }
    }
  ]
  name "solid(4)"
  contactMaterial "box"
  boundingObject USE BOX_R
  physics Physics {
  }
}
DEF Block_R2 Solid {
  translation 1 0.05 0.3
  children [
    USE BOX_R
  ]
  name "solid(13)"
  contactMaterial "block"
  boundingObject USE BOX_R
  physics Physics {
  }
}
DEF Block_R3 Solid {
  translation -1 0.05 -0.5
  children [
    USE BOX_R
  ]
  name "solid(12)"
  boundingObject USE BOX_R
  physics Physics {
  }
}
DEF Block_R4 Solid {
  translation 0.1 0.05 1.1
  children [
    USE BOX_R
  ]
  name "solid(7)"
  boundingObject USE BOX_R
  physics Physics {
  }
}
DEF Block_B1 Solid {
  translation -1.1 0.05 1
  children [
    DEF BOX_B Shape {
      appearance PBRAppearance {
        baseColor 0 0 1
        metalness 0
      }
      geometry Box {
        size 0.05 0.05 0.05
      }
    }
  ]
  name "solid(8)"
  boundingObject USE BOX_B
  physics Physics {
  }
}
DEF Block_B2 Solid {
  translation 0.03 0.05 0.72
  children [
    USE BOX_B
  ]
  name "solid(9)"
  boundingObject USE BOX_B
  physics Physics {
  }
}
DEF Block_B3 Solid {
  translation -0.85 0.05 -0.2
  children [
    USE BOX_B
  ]
  name "solid(10)"
  boundingObject USE BOX_B
  physics Physics {
  }
}
DEF Block_B4 Solid {
  translation 1 0.05 0.7
  children [
    USE BOX_B
  ]
  name "solid(11)"
  boundingObject USE BOX_B
  physics Physics {
  }
}
DEF Floor_colour Solid {
  translation 1 0.0001 1
  children [
    Shape {
      appearance PBRAppearance {
        baseColor 1 0 0
      }
      geometry Plane {
        size 0.4 0.4
      }
    }
  ]
  name "solid(6)"
}
DEF Floor_colour Solid {
  translation 1 0.0001 -1
  children [
    Shape {
      appearance PBRAppearance {
        baseColor 0 0 1
      }
      geometry Plane {
        size 0.4 0.4
      }
    }
  ]
  name "solid(5)"
}
DEF WALL_1 Solid {
  translation 1.2 0.05 0
  children [
    DEF WALL_SHAPE Shape {
      appearance PBRAppearance {
        baseColor 0.12549 0.368627 0.729412
        roughness 1
        metalness 0
      }
      geometry Box {
        size 0.02 0.1 2.38
      }
    }
  ]
  boundingObject USE WALL_SHAPE
}
DEF WALL_2 Solid {
  translation -1.2 0.05 0
  children [
    USE WALL_SHAPE
  ]
  name "solid(1)"
  boundingObject USE WALL_SHAPE
}
DEF WALL_3 Solid {
  translation 0 0.05 -1.2
  rotation 0 1 0 1.5708
  children [
    USE WALL_SHAPE
  ]
  name "solid(2)"
  boundingObject USE WALL_SHAPE
}
DEF WALL_4 Solid {
  translation 0 0.05 1.2
  rotation 0 1 0 1.5708
  children [
    USE WALL_SHAPE
  ]
  name "solid(3)"
  boundingObject USE WALL_SHAPE
}
Robot {
  translation 1 0.06 1
  children [
    SharpGP2Y0A02YK0F {
      translation 0.01 0 -0.12
      rotation 0 1 0 1.5708
      name "distance1"
    }
    Compass {
    }
    Receiver {
      channel 1
    }
    Emitter {
      channel 1
    }
    GPS {
    }
    Camera {
      translation 0 0 0.1
      width 1
      height 1
    }
    Solid {
      translation 0 -0.03 0
      children [
        Shape {
          geometry DEF CASTOR_BALL Sphere {
            radius 0.01
          }
        }
      ]
      name "solid(2)"
      contactMaterial "slippy"
      boundingObject USE CASTOR_BALL
      physics Physics {
      }
    }
    DEF BODY Shape {
      appearance PBRAppearance {
        baseColor 1 0 0
        roughness 1
        metalness 0
      }
      geometry Box {
        size 0.1 0.05 0.2
      }
    }
    DEF WHEEL1 HingeJoint {
      jointParameters HingeJointParameters {
        anchor 0.06 0 0.05
      }
      device [
        RotationalMotor {
          name "wheel1"
          maxTorque 100
        }
      ]
      endPoint Solid {
        translation 0.06000559915048376 4.758333689287461e-06 0.049998786434356526
        rotation 0.0022067604511290654 -0.002042188058717539 -0.9999954798279062 4.712367251344767
        children [
          DEF WHEEL Shape {
            appearance PBRAppearance {
              baseColor 0.305882 0.898039 0.25098
              roughness 1
              metalness 0
            }
            geometry Cylinder {
              height 0.02
              radius 0.04
              subdivision 24
            }
          }
        ]
        boundingObject USE WHEEL
        physics Physics {
        }
      }
    }
    DEF WHEEL2 HingeJoint {
      jointParameters HingeJointParameters {
        anchor -0.06 0 0.05
      }
      device [
        RotationalMotor {
          name "wheel2"
          maxTorque 100
        }
      ]
      endPoint Solid {
        translation -0.06000535798759132 -4.4653555259419955e-06 0.04999811264477753
        rotation 0.0015698858926353123 -0.0014057992196956344 -0.999997779590954 4.712402291649479
        children [
          USE WHEEL
        ]
        name "solid(1)"
        boundingObject USE WHEEL
        physics Physics {
        }
      }
    }
    DEF DS_RIGHT DistanceSensor {
      translation -0.03 0 0.1
      rotation 0 1 0 -1.87079
      children [
        Shape {
          appearance PBRAppearance {
            baseColor 0.184314 0.596078 0.847059
            roughness 1
            metalness 0
          }
          geometry Box {
            size 0.01 0.01 0.01
          }
        }
      ]
      name "ds_right"
      model "GP2Y0A710K0F"
    }
    DEF DS_LEFT DistanceSensor {
      translation 0.03 0 0.1
      rotation 0 1 0 -1.27079
      children [
        Shape {
          appearance PBRAppearance {
            baseColor 0.184314 0.596078 0.847059
            roughness 1
            metalness 0
          }
          geometry Box {
            size 0.01 0.01 0.01
          }
        }
      ]
      name "ds_left"
    }
  ]
  boundingObject USE BODY
  physics Physics {
    density -1
    mass 1
  }
  controller "collector_bot"
}
Robot {
  children [
    Emitter {
      name "emitter_blue"
    }
    Receiver {
      name "receiver_blue"
      channel 2
    }
    Emitter {
      name "emitter_red"
      channel 1
    }
    Receiver {
      name "receiver_red"
      channel 1
    }
  ]
  name "shared"
  controller "shared_controller"
}
